2024-08-03 09:46:54,627 - INFO - "GET / HTTP/1.1" 200 721
2024-08-03 09:46:54,753 - INFO - "GET /static/css/main.0d1ad0bf.css HTTP/1.1" 200 5334
2024-08-03 09:46:54,753 - INFO - "GET /static/js/main.45cf327c.js HTTP/1.1" 200 308552
2024-08-03 09:46:54,975 - WARNING - Not Found: /favicon.ico
2024-08-03 09:46:54,975 - WARNING - "GET /favicon.ico HTTP/1.1" 404 2889
2024-08-03 09:47:03,941 - INFO - "OPTIONS /auth/signup HTTP/1.1" 200 0
2024-08-03 09:47:04,009 - INFO - "POST /auth/signup HTTP/1.1" 200 41
2024-08-03 09:47:25,171 - WARNING - Bad Request: /auth/signup
2024-08-03 09:47:25,171 - WARNING - "POST /auth/signup HTTP/1.1" 400 78
2024-08-03 09:47:39,389 - INFO - "OPTIONS /auth/token/ HTTP/1.1" 200 0
2024-08-03 09:47:39,454 - INFO - "POST /auth/token/ HTTP/1.1" 200 483
2024-08-03 09:47:39,515 - INFO - "OPTIONS /datasets?page=1 HTTP/1.1" 200 0
2024-08-03 09:47:39,558 - INFO - "GET /datasets?page=1 HTTP/1.1" 301 0
2024-08-03 09:47:39,604 - INFO - "OPTIONS /datasets/?page=1 HTTP/1.1" 200 0
2024-08-03 09:47:39,678 - ERROR - Internal Server Error: /datasets/
Traceback (most recent call last):
  File "/home/reyes/miniconda3/envs/tfg/lib/python3.8/site-packages/django/db/backends/utils.py", line 84, in _execute
    return self.cursor.execute(sql, params)
psycopg2.errors.UndefinedTable: relation "datasets_datasets" does not exist
LINE 1: SELECT COUNT(*) AS "__count" FROM "datasets_datasets" WHERE ...
                                          ^


The above exception was the direct cause of the following exception:

Traceback (most recent call last):
  File "/home/reyes/miniconda3/envs/tfg/lib/python3.8/site-packages/django/core/handlers/exception.py", line 47, in inner
    response = get_response(request)
  File "/home/reyes/miniconda3/envs/tfg/lib/python3.8/site-packages/django/core/handlers/base.py", line 181, in _get_response
    response = wrapped_callback(request, *callback_args, **callback_kwargs)
  File "/home/reyes/miniconda3/envs/tfg/lib/python3.8/site-packages/django/views/decorators/csrf.py", line 54, in wrapped_view
    return view_func(*args, **kwargs)
  File "/home/reyes/miniconda3/envs/tfg/lib/python3.8/site-packages/django/views/generic/base.py", line 70, in view
    return self.dispatch(request, *args, **kwargs)
  File "/home/reyes/miniconda3/envs/tfg/lib/python3.8/site-packages/rest_framework/views.py", line 509, in dispatch
    response = self.handle_exception(exc)
  File "/home/reyes/miniconda3/envs/tfg/lib/python3.8/site-packages/rest_framework/views.py", line 469, in handle_exception
    self.raise_uncaught_exception(exc)
  File "/home/reyes/miniconda3/envs/tfg/lib/python3.8/site-packages/rest_framework/views.py", line 480, in raise_uncaught_exception
    raise exc
  File "/home/reyes/miniconda3/envs/tfg/lib/python3.8/site-packages/rest_framework/views.py", line 506, in dispatch
    response = handler(request, *args, **kwargs)
  File "/home/reyes/miniconda3/envs/tfg/lib/python3.8/site-packages/rest_framework/decorators.py", line 50, in handler
    return func(*args, **kwargs)
  File "/home/reyes/tfg/datasets/views.py", line 47, in datasets
    if datasets.count() < datasetsPerPage:
  File "/home/reyes/miniconda3/envs/tfg/lib/python3.8/site-packages/django/db/models/query.py", line 412, in count
    return self.query.get_count(using=self.db)
  File "/home/reyes/miniconda3/envs/tfg/lib/python3.8/site-packages/django/db/models/sql/query.py", line 528, in get_count
    number = obj.get_aggregation(using, ['__count'])['__count']
  File "/home/reyes/miniconda3/envs/tfg/lib/python3.8/site-packages/django/db/models/sql/query.py", line 513, in get_aggregation
    result = compiler.execute_sql(SINGLE)
  File "/home/reyes/miniconda3/envs/tfg/lib/python3.8/site-packages/django/db/models/sql/compiler.py", line 1175, in execute_sql
    cursor.execute(sql, params)
  File "/home/reyes/miniconda3/envs/tfg/lib/python3.8/site-packages/django/db/backends/utils.py", line 98, in execute
    return super().execute(sql, params)
  File "/home/reyes/miniconda3/envs/tfg/lib/python3.8/site-packages/django/db/backends/utils.py", line 66, in execute
    return self._execute_with_wrappers(sql, params, many=False, executor=self._execute)
  File "/home/reyes/miniconda3/envs/tfg/lib/python3.8/site-packages/django/db/backends/utils.py", line 75, in _execute_with_wrappers
    return executor(sql, params, many, context)
  File "/home/reyes/miniconda3/envs/tfg/lib/python3.8/site-packages/django/db/backends/utils.py", line 84, in _execute
    return self.cursor.execute(sql, params)
  File "/home/reyes/miniconda3/envs/tfg/lib/python3.8/site-packages/django/db/utils.py", line 90, in __exit__
    raise dj_exc_value.with_traceback(traceback) from exc_value
  File "/home/reyes/miniconda3/envs/tfg/lib/python3.8/site-packages/django/db/backends/utils.py", line 84, in _execute
    return self.cursor.execute(sql, params)
django.db.utils.ProgrammingError: relation "datasets_datasets" does not exist
LINE 1: SELECT COUNT(*) AS "__count" FROM "datasets_datasets" WHERE ...
                                          ^

2024-08-03 09:47:39,680 - ERROR - "GET /datasets/?page=1 HTTP/1.1" 500 152171
2024-08-03 09:48:49,949 - INFO - "GET / HTTP/1.1" 200 721
2024-08-03 09:48:49,994 - INFO - "GET /static/js/main.45cf327c.js HTTP/1.1" 304 0
2024-08-03 09:48:49,994 - INFO - "GET /static/css/main.0d1ad0bf.css HTTP/1.1" 304 0
2024-08-03 09:51:40,056 - INFO - "OPTIONS /auth/token/refresh/ HTTP/1.1" 200 0
2024-08-03 09:51:40,076 - INFO - "POST /auth/token/refresh/ HTTP/1.1" 200 483
2024-08-03 09:52:27,739 - ERROR - Internal Server Error: /datasets/
Traceback (most recent call last):
  File "/home/reyes/miniconda3/envs/tfg/lib/python3.8/site-packages/django/core/handlers/exception.py", line 47, in inner
    response = get_response(request)
  File "/home/reyes/miniconda3/envs/tfg/lib/python3.8/site-packages/django/core/handlers/base.py", line 181, in _get_response
    response = wrapped_callback(request, *callback_args, **callback_kwargs)
  File "/home/reyes/miniconda3/envs/tfg/lib/python3.8/site-packages/django/views/decorators/csrf.py", line 54, in wrapped_view
    return view_func(*args, **kwargs)
  File "/home/reyes/miniconda3/envs/tfg/lib/python3.8/site-packages/django/views/generic/base.py", line 70, in view
    return self.dispatch(request, *args, **kwargs)
  File "/home/reyes/miniconda3/envs/tfg/lib/python3.8/site-packages/rest_framework/views.py", line 509, in dispatch
    response = self.handle_exception(exc)
  File "/home/reyes/miniconda3/envs/tfg/lib/python3.8/site-packages/rest_framework/views.py", line 469, in handle_exception
    self.raise_uncaught_exception(exc)
  File "/home/reyes/miniconda3/envs/tfg/lib/python3.8/site-packages/rest_framework/views.py", line 480, in raise_uncaught_exception
    raise exc
  File "/home/reyes/miniconda3/envs/tfg/lib/python3.8/site-packages/rest_framework/views.py", line 506, in dispatch
    response = handler(request, *args, **kwargs)
  File "/home/reyes/miniconda3/envs/tfg/lib/python3.8/site-packages/rest_framework/decorators.py", line 50, in handler
    return func(*args, **kwargs)
  File "/home/reyes/tfg/datasets/views.py", line 54, in datasets
    total_pages = math.ceil(datasets.count() / page_size)
ZeroDivisionError: division by zero
2024-08-03 09:52:27,739 - ERROR - "GET /datasets/?page=1 HTTP/1.1" 500 98224
